Workbook

Sheet 射擊表
A1: 洞口 | B1: 距離(m) | C1: 仰角(us) | D1: 轉速 | E1: 轉速單位
A2: 4 | B2: 2.85 | C2: 500 | D2: 37 | E2: %
A3: 4 | B3: 3.26 | C3: 500 | D3: 37 | E3: %
A4: 4 | B4: 3.66 | C4: 500 | D4: 38 | E4: %
A5: 4 | B5: 4.1 | C5: 608 | D5: 38 | E5: %
A6: 4 | B6: 4.44 | C6: 500 | D6: 41 | E6: %
A7: 4 | B7: 5.12 | C7: 500 | D7: 42 | E7: %
A8: 4 | B8: 5.48 | C8: 500 | D8: 42 | E8: %
A9: 4 | B9: 5.9 | C9: 500 | D9: 44 | E9: %
A10: 4 | B10: 6.36 | C10: 500 | D10: 47 | E10: %
A11: 4 | B11: 6.75 | C11: 500 | D11: 48 | E11: %
A12: 4 | B12: 7.32 | C12: 500 | D12: 49 | E12: %
A13: 5 | B13: 7.49 | C13: 500 | D13: 55 | E13: %
... A27: 6 | B27: 4.7 | C27: 865 | D27: 65 | E27: %

Sheet 說明
A1: 射擊表怎麼用
A3: 1. 在「射擊表」工作表改數字、加列、刪列，存檔（保持 .xlsx）。旁邊三張射擊曲線圖（下、中、上排，用中間那一行的洞口 4、5、6）會自動跟著更新。
A4: 2. 在專案資料夾執行：python3 tools/shot_table/apply.py --upload
A5: 會檢查格式、列出改了哪些值、產生 src/Constants/ShotTableData.h，再燒進 Mega。
A6: 只想檢查：python3 tools/shot_table/apply.py --check
A8: 格式（嚴格）
A9: - 第 1 列是欄位名稱。「洞口」「距離(m)」「仰角(us)」「轉速」「轉速單位」五個必須各出現一次、名稱一字不差。
A10: - 若插入其他欄位，新欄位一定要有名稱；它們不會被讀取。
A11: - 洞口：Dashboard 的編號 1–9（1 左下、2 左中、3 左上 … 9 右上）；10、11、12 是最上面的加分框左、中、右（Dashboard 按 Q、W、E 選）。
A12: - 距離：鎖定目標時 Dashboard 顯示的相機距離（不是捲尺），0.5–15 m，最多 2 位小數。
A13: - 仰角：Dashboard 的仰角脈寬，500–2500 的整數。
A14: - 轉速單位：用下拉選單選「%」或「us」，每一列可以不同。
... A25: 「圖表資料」是隱藏的工作表，由公式自動整理給曲線圖用，不用動它。

Sheet 圖表資料
A1: 洞口4 距離 | B1: 洞口4 仰角 | C1: 洞口4 轉速 | D1: 洞口5 距離 | E1: 洞口5 仰角 | F1: 洞口5 轉速 | G1: 洞口6 距離 | H1: 洞口6 仰角 | I1: 洞口6 轉速
A2: {=IFERROR(SMALL(IF('射擊表'!$A$2:$A$500=4,'射擊表'!$B$2:$B$500),1),NA())} | B2: {=IFERROR(INDEX('射擊表'!$C$2:$C$500,MATCH(1,('射擊表'!$A$2:$A$500=4)*('射擊表'!$B$2:$B$500=A2),0)),NA())} | C2: {=IFERROR(INDEX(IF('射擊表'!$E$2:$E$500="us",ABS('射擊表'!$D$2:$D$500-1500)/5,'射擊表'!$D$2:$D$500),MATCH(1,('射擊表'!$A$2:$A$500=4)*('射擊表'!$B$2:$B$500=A2),0)),NA())} | D2: {=IFERROR(SMALL(IF('射擊表'!$A$2:$A$500=5,'射擊表'!$B$2:$B$500),1),NA())} | E2: {=IFERROR(INDEX('射擊表'!$C$2:$C$500,MATCH(1,('射擊表'!$A$2:$A$500=5)*('射擊表'!$B$2:$B$500=D2),0)),NA())} | F2: {=IFERROR(INDEX(IF('射擊表'!$E$2:$E$500="us",ABS('射擊表'!$D$2:$D$500-1500)/5,'射擊表'!$D$2:$D$500),MATCH(1,('射擊表'!$A$2:$A$500=5)*('射擊表'!$B$2:$B$500=D2),0)),NA())} | G2: {=IFERROR(SMALL(IF('射擊表'!$A$2:$A$500=6,'射擊表'!$B$2:$B$500),1),NA())} | H2: {=IFERROR(INDEX('射擊表'!$C$2:$C$500,MATCH(1,('射擊表'!$A$2:$A$500=6)*('射擊表'!$B$2:$B$500=G2),0)),NA())} | I2: {=IFERROR(INDEX(IF('射擊表'!$E$2:$E$500="us",ABS('射擊表'!$D$2:$D$500-1500)/5,'射擊表'!$D$2:$D$500),MATCH(1,('射擊表'!$A$2:$A$500=6)*('射擊表'!$B$2:$B$500=G2),0)),NA())}
A3: {=IFERROR(SMALL(IF('射擊表'!$A$2:$A$500=4,'射擊表'!$B$2:$B$500),2),NA())} | B3: {=IFERROR(INDEX('射擊表'!$C$2:$C$500,MATCH(1,('射擊表'!$A$2:$A$500=4)*('射擊表'!$B$2:$B$500=A3),0)),NA())} | C3: {=IFERROR(INDEX(IF('射擊表'!$E$2:$E$500="us",ABS('射擊表'!$D$2:$D$500-1500)/5,'射擊表'!$D$2:$D$500),MATCH(1,('射擊表'!$A$2:$A$500=4)*('射擊表'!$B$2:$B$500=A3),0)),NA())} | D3: {=IFERROR(SMALL(IF('射擊表'!$A$2:$A$500=5,'射擊表'!$B$2:$B$500),2),NA())} | E3: {=IFERROR(INDEX('射擊表'!$C$2:$C$500,MATCH(1,('射擊表'!$A$2:$A$500=5)*('射擊表'!$B$2:$B$500=D3),0)),NA())} | F3: {=IFERROR(INDEX(IF('射擊表'!$E$2:$E$500="us",ABS('射擊表'!$D$2:$D$500-1500)/5,'射擊表'!$D$2:$D$500),MATCH(1,('射擊表'!$A$2:$A$500=5)*('射擊表'!$B$2:$B$500=D3),0)),NA())} | G3: {=IFERROR(SMALL(IF('射擊表'!$A$2:$A$500=6,'射擊表'!$B$2:$B$500),2),NA())} | H3: {=IFERROR(INDEX('射擊表'!$C$2:$C$500,MATCH(1,('射擊表'!$A$2:$A$500=6)*('射擊表'!$B$2:$B$500=G3),0)),NA())} | I3: {=IFERROR(INDEX(IF('射擊表'!$E$2:$E$500="us",ABS('射擊表'!$D$2:$D$500-1500)/5,'射擊表'!$D$2:$D$500),MATCH(1,('射擊表'!$A$2:$A$500=6)*('射擊表'!$B$2:$B$500=G3),0)),NA())}
A4: {=IFERROR(SMALL(IF('射擊表'!$A$2:$A$500=4,'射擊表'!$B$2:$B$500),3),NA())} | B4: {=IFERROR(INDEX('射擊表'!$C$2:$C$500,MATCH(1,('射擊表'!$A$2:$A$500=4)*('射擊表'!$B$2:$B$500=A4),0)),NA())} | C4: {=IFERROR(INDEX(IF('射擊表'!$E$2:$E$500="us",ABS('射擊表'!$D$2:$D$500-1500)/5,'射擊表'!$D$2:$D$500),MATCH(1,('射擊表'!$A$2:$A$500=4)*('射擊表'!$B$2:$B$500=A4),0)),NA())} | D4: {=IFERROR(SMALL(IF('射擊表'!$A$2:$A$500=5,'射擊表'!$B$2:$B$500),3),NA())} | E4: {=IFERROR(INDEX('射擊表'!$C$2:$C$500,MATCH(1,('射擊表'!$A$2:$A$500=5)*('射擊表'!$B$2:$B$500=D4),0)),NA())} | F4: {=IFERROR(INDEX(IF('射擊表'!$E$2:$E$500="us",ABS('射擊表'!$D$2:$D$500-1500)/5,'射擊表'!$D$2:$D$500),MATCH(1,('射擊表'!$A$2:$A$500=5)*('射擊表'!$B$2:$B$500=D4),0)),NA())} | G4: {=IFERROR(SMALL(IF('射擊表'!$A$2:$A$500=6,'射擊表'!$B$2:$B$500),3),NA())} | H4: {=IFERROR(INDEX('射擊表'!$C$2:$C$500,MATCH(1,('射擊表'!$A$2:$A$500=6)*('射擊表'!$B$2:$B$500=G4),0)),NA())} | I4: {=IFERROR(INDEX(IF('射擊表'!$E$2:$E$500="us",ABS('射擊表'!$D$2:$D$500-1500)/5,'射擊表'!$D$2:$D$500),MATCH(1,('射擊表'!$A$2:$A$500=6)*('射擊表'!$B$2:$B$500=G4),0)),NA())}
A5: {=IFERROR(SMALL(IF('射擊表'!$A$2:$A$500=4,'射擊表'!$B$2:$B$500),4),NA())} | B5: {=IFERROR(INDEX('射擊表'!$C$2:$C$500,MATCH(1,('射擊表'!$A$2:$A$500=4)*('射擊表'!$B$2:$B$500=A5),0)),NA())} | C5: {=IFERROR(INDEX(IF('射擊表'!$E$2:$E$500="us",ABS('射擊表'!$D$2:$D$500-1500)/5,'射擊表'!$D$2:$D$500),MATCH(1,('射擊表'!$A$2:$A$500=4)*('射擊表'!$B$2:$B$500=A5),0)),NA())} | D5: {=IFERROR(SMALL(IF('射擊表'!$A$2:$A$500=5,'射擊表'!$B$2:$B$500),4),NA())} | E5: {=IFERROR(INDEX('射擊表'!$C$2:$C$500,MATCH(1,('射擊表'!$A$2:$A$500=5)*('射擊表'!$B$2:$B$500=D5),0)),NA())} | F5: {=IFERROR(INDEX(IF('射擊表'!$E$2:$E$500="us",ABS('射擊表'!$D$2:$D$500-1500)/5,'射擊表'!$D$2:$D$500),MATCH(1,('射擊表'!$A$2:$A$500=5)*('射擊表'!$B$2:$B$500=D5),0)),NA())} | G5: {=IFERROR(SMALL(IF('射擊表'!$A$2:$A$500=6,'射擊表'!$B$2:$B$500),4),NA())} | H5: {=IFERROR(INDEX('射擊表'!$C$2:$C$500,MATCH(1,('射擊表'!$A$2:$A$500=6)*('射擊表'!$B$2:$B$500=G5),0)),NA())} | I5: {=IFERROR(INDEX(IF('射擊表'!$E$2:$E$500="us",ABS('射擊表'!$D$2:$D$500-1500)/5,'射擊表'!$D$2:$D$500),MATCH(1,('射擊表'!$A$2:$A$500=6)*('射擊表'!$B$2:$B$500=G5),0)),NA())}
A6: {=IFERROR(SMALL(IF('射擊表'!$A$2:$A$500=4,'射擊表'!$B$2:$B$500),5),NA())} | B6: {=IFERROR(INDEX('射擊表'!$C$2:$C$500,MATCH(1,('射擊表'!$A$2:$A$500=4)*('射擊表'!$B$2:$B$500=A6),0)),NA())} | C6: {=IFERROR(INDEX(IF('射擊表'!$E$2:$E$500="us",ABS('射擊表'!$D$2:$D$500-1500)/5,'射擊表'!$D$2:$D$500),MATCH(1,('射擊表'!$A$2:$A$500=4)*('射擊表'!$B$2:$B$500=A6),0)),NA())} | D6: {=IFERROR(SMALL(IF('射擊表'!$A$2:$A$500=5,'射擊表'!$B$2:$B$500),5),NA())} | E6: {=IFERROR(INDEX('射擊表'!$C$2:$C$500,MATCH(1,('射擊表'!$A$2:$A$500=5)*('射擊表'!$B$2:$B$500=D6),0)),NA())} | F6: {=IFERROR(INDEX(IF('射擊表'!$E$2:$E$500="us",ABS('射擊表'!$D$2:$D$500-1500)/5,'射擊表'!$D$2:$D$500),MATCH(1,('射擊表'!$A$2:$A$500=5)*('射擊表'!$B$2:$B$500=D6),0)),NA())} | G6: {=IFERROR(SMALL(IF('射擊表'!$A$2:$A$500=6,'射擊表'!$B$2:$B$500),5),NA())} | H6: {=IFERROR(INDEX('射擊表'!$C$2:$C$500,MATCH(1,('射擊表'!$A$2:$A$500=6)*('射擊表'!$B$2:$B$500=G6),0)),NA())} | I6: {=IFERROR(INDEX(IF('射擊表'!$E$2:$E$500="us",ABS('射擊表'!$D$2:$D$500-1500)/5,'射擊表'!$D$2:$D$500),MATCH(1,('射擊表'!$A$2:$A$500=6)*('射擊表'!$B$2:$B$500=G6),0)),NA())}
A7: {=IFERROR(SMALL(IF('射擊表'!$A$2:$A$500=4,'射擊表'!$B$2:$B$500),6),NA())} | B7: {=IFERROR(INDEX('射擊表'!$C$2:$C$500,MATCH(1,('射擊表'!$A$2:$A$500=4)*('射擊表'!$B$2:$B$500=A7),0)),NA())} | C7: {=IFERROR(INDEX(IF('射擊表'!$E$2:$E$500="us",ABS('射擊表'!$D$2:$D$500-1500)/5,'射擊表'!$D$2:$D$500),MATCH(1,('射擊表'!$A$2:$A$500=4)*('射擊表'!$B$2:$B$500=A7),0)),NA())} | D7: {=IFERROR(SMALL(IF('射擊表'!$A$2:$A$500=5,'射擊表'!$B$2:$B$500),6),NA())} | E7: {=IFERROR(INDEX('射擊表'!$C$2:$C$500,MATCH(1,('射擊表'!$A$2:$A$500=5)*('射擊表'!$B$2:$B$500=D7),0)),NA())} | F7: {=IFERROR(INDEX(IF('射擊表'!$E$2:$E$500="us",ABS('射擊表'!$D$2:$D$500-1500)/5,'射擊表'!$D$2:$D$500),MATCH(1,('射擊表'!$A$2:$A$500=5)*('射擊表'!$B$2:$B$500=D7),0)),NA())} | G7: {=IFERROR(SMALL(IF('射擊表'!$A$2:$A$500=6,'射擊表'!$B$2:$B$500),6),NA())} | H7: {=IFERROR(INDEX('射擊表'!$C$2:$C$500,MATCH(1,('射擊表'!$A$2:$A$500=6)*('射擊表'!$B$2:$B$500=G7),0)),NA())} | I7: {=IFERROR(INDEX(IF('射擊表'!$E$2:$E$500="us",ABS('射擊表'!$D$2:$D$500-1500)/5,'射擊表'!$D$2:$D$500),MATCH(1,('射擊表'!$A$2:$A$500=6)*('射擊表'!$B$2:$B$500=G7),0)),NA())}
A8: {=IFERROR(SMALL(IF('射擊表'!$A$2:$A$500=4,'射擊表'!$B$2:$B$500),7),NA())} | B8: {=IFERROR(INDEX('射擊表'!$C$2:$C$500,MATCH(1,('射擊表'!$A$2:$A$500=4)*('射擊表'!$B$2:$B$500=A8),0)),NA())} | C8: {=IFERROR(INDEX(IF('射擊表'!$E$2:$E$500="us",ABS('射擊表'!$D$2:$D$500-1500)/5,'射擊表'!$D$2:$D$500),MATCH(1,('射擊表'!$A$2:$A$500=4)*('射擊表'!$B$2:$B$500=A8),0)),NA())} | D8: {=IFERROR(SMALL(IF('射擊表'!$A$2:$A$500=5,'射擊表'!$B$2:$B$500),7),NA())} | E8: {=IFERROR(INDEX('射擊表'!$C$2:$C$500,MATCH(1,('射擊表'!$A$2:$A$500=5)*('射擊表'!$B$2:$B$500=D8),0)),NA())} | F8: {=IFERROR(INDEX(IF('射擊表'!$E$2:$E$500="us",ABS('射擊表'!$D$2:$D$500-1500)/5,'射擊表'!$D$2:$D$500),MATCH(1,('射擊表'!$A$2:$A$500=5)*('射擊表'!$B$2:$B$500=D8),0)),NA())} | G8: {=IFERROR(SMALL(IF('射擊表'!$A$2:$A$500=6,'射擊表'!$B$2:$B$500),7),NA())} | H8: {=IFERROR(INDEX('射擊表'!$C$2:$C$500,MATCH(1,('射擊表'!$A$2:$A$500=6)*('射擊表'!$B$2:$B$500=G8),0)),NA())} | I8: {=IFERROR(INDEX(IF('射擊表'!$E$2:$E$500="us",ABS('射擊表'!$D$2:$D$500-1500)/5,'射擊表'!$D$2:$D$500),MATCH(1,('射擊表'!$A$2:$A$500=6)*('射擊表'!$B$2:$B$500=G8),0)),NA())}
A9: {=IFERROR(SMALL(IF('射擊表'!$A$2:$A$500=4,'射擊表'!$B$2:$B$500),8),NA())} | B9: {=IFERROR(INDEX('射擊表'!$C$2:$C$500,MATCH(1,('射擊表'!$A$2:$A$500=4)*('射擊表'!$B$2:$B$500=A9),0)),NA())} | C9: {=IFERROR(INDEX(IF('射擊表'!$E$2:$E$500="us",ABS('射擊表'!$D$2:$D$500-1500)/5,'射擊表'!$D$2:$D$500),MATCH(1,('射擊表'!$A$2:$A$500=4)*('射擊表'!$B$2:$B$500=A9),0)),NA())} | D9: {=IFERROR(SMALL(IF('射擊表'!$A$2:$A$500=5,'射擊表'!$B$2:$B$500),8),NA())} | E9: {=IFERROR(INDEX('射擊表'!$C$2:$C$500,MATCH(1,('射擊表'!$A$2:$A$500=5)*('射擊表'!$B$2:$B$500=D9),0)),NA())} | F9: {=IFERROR(INDEX(IF('射擊表'!$E$2:$E$500="us",ABS('射擊表'!$D$2:$D$500-1500)/5,'射擊表'!$D$2:$D$500),MATCH(1,('射擊表'!$A$2:$A$500=5)*('射擊表'!$B$2:$B$500=D9),0)),NA())} | G9: {=IFERROR(SMALL(IF('射擊表'!$A$2:$A$500=6,'射擊表'!$B$2:$B$500),8),NA())} | H9: {=IFERROR(INDEX('射擊表'!$C$2:$C$500,MATCH(1,('射擊表'!$A$2:$A$500=6)*('射擊表'!$B$2:$B$500=G9),0)),NA())} | I9: {=IFERROR(INDEX(IF('射擊表'!$E$2:$E$500="us",ABS('射擊表'!$D$2:$D$500-1500)/5,'射擊表'!$D$2:$D$500),MATCH(1,('射擊表'!$A$2:$A$500=6)*('射擊表'!$B$2:$B$500=G9),0)),NA())}
A10: {=IFERROR(SMALL(IF('射擊表'!$A$2:$A$500=4,'射擊表'!$B$2:$B$500),9),NA())} | B10: {=IFERROR(INDEX('射擊表'!$C$2:$C$500,MATCH(1,('射擊表'!$A$2:$A$500=4)*('射擊表'!$B$2:$B$500=A10),0)),NA())} | C10: {=IFERROR(INDEX(IF('射擊表'!$E$2:$E$500="us",ABS('射擊表'!$D$2:$D$500-1500)/5,'射擊表'!$D$2:$D$500),MATCH(1,('射擊表'!$A$2:$A$500=4)*('射擊表'!$B$2:$B$500=A10),0)),NA())} | D10: {=IFERROR(SMALL(IF('射擊表'!$A$2:$A$500=5,'射擊表'!$B$2:$B$500),9),NA())} | E10: {=IFERROR(INDEX('射擊表'!$C$2:$C$500,MATCH(1,('射擊表'!$A$2:$A$500=5)*('射擊表'!$B$2:$B$500=D10),0)),NA())} | F10: {=IFERROR(INDEX(IF('射擊表'!$E$2:$E$500="us",ABS('射擊表'!$D$2:$D$500-1500)/5,'射擊表'!$D$2:$D$500),MATCH(1,('射擊表'!$A$2:$A$500=5)*('射擊表'!$B$2:$B$500=D10),0)),NA())} | G10: {=IFERROR(SMALL(IF('射擊表'!$A$2:$A$500=6,'射擊表'!$B$2:$B$500),9),NA())} | H10: {=IFERROR(INDEX('射擊表'!$C$2:$C$500,MATCH(1,('射擊表'!$A$2:$A$500=6)*('射擊表'!$B$2:$B$500=G10),0)),NA())} | I10: {=IFERROR(INDEX(IF('射擊表'!$E$2:$E$500="us",ABS('射擊表'!$D$2:$D$500-1500)/5,'射擊表'!$D$2:$D$500),MATCH(1,('射擊表'!$A$2:$A$500=6)*('射擊表'!$B$2:$B$500=G10),0)),NA())}
A11: {=IFERROR(SMALL(IF('射擊表'!$A$2:$A$500=4,'射擊表'!$B$2:$B$500),10),NA())} | B11: {=IFERROR(INDEX('射擊表'!$C$2:$C$500,MATCH(1,('射擊表'!$A$2:$A$500=4)*('射擊表'!$B$2:$B$500=A11),0)),NA())} | C11: {=IFERROR(INDEX(IF('射擊表'!$E$2:$E$500="us",ABS('射擊表'!$D$2:$D$500-1500)/5,'射擊表'!$D$2:$D$500),MATCH(1,('射擊表'!$A$2:$A$500=4)*('射擊表'!$B$2:$B$500=A11),0)),NA())} | D11: {=IFERROR(SMALL(IF('射擊表'!$A$2:$A$500=5,'射擊表'!$B$2:$B$500),10),NA())} | E11: {=IFERROR(INDEX('射擊表'!$C$2:$C$500,MATCH(1,('射擊表'!$A$2:$A$500=5)*('射擊表'!$B$2:$B$500=D11),0)),NA())} | F11: {=IFERROR(INDEX(IF('射擊表'!$E$2:$E$500="us",ABS('射擊表'!$D$2:$D$500-1500)/5,'射擊表'!$D$2:$D$500),MATCH(1,('射擊表'!$A$2:$A$500=5)*('射擊表'!$B$2:$B$500=D11),0)),NA())} | G11: {=IFERROR(SMALL(IF('射擊表'!$A$2:$A$500=6,'射擊表'!$B$2:$B$500),10),NA())} | H11: {=IFERROR(INDEX('射擊表'!$C$2:$C$500,MATCH(1,('射擊表'!$A$2:$A$500=6)*('射擊表'!$B$2:$B$500=G11),0)),NA())} | I11: {=IFERROR(INDEX(IF('射擊表'!$E$2:$E$500="us",ABS('射擊表'!$D$2:$D$500-1500)/5,'射擊表'!$D$2:$D$500),MATCH(1,('射擊表'!$A$2:$A$500=6)*('射擊表'!$B$2:$B$500=G11),0)),NA())}
A12: {=IFERROR(SMALL(IF('射擊表'!$A$2:$A$500=4,'射擊表'!$B$2:$B$500),11),NA())} | B12: {=IFERROR(INDEX('射擊表'!$C$2:$C$500,MATCH(1,('射擊表'!$A$2:$A$500=4)*('射擊表'!$B$2:$B$500=A12),0)),NA())} | C12: {=IFERROR(INDEX(IF('射擊表'!$E$2:$E$500="us",ABS('射擊表'!$D$2:$D$500-1500)/5,'射擊表'!$D$2:$D$500),MATCH(1,('射擊表'!$A$2:$A$500=4)*('射擊表'!$B$2:$B$500=A12),0)),NA())} | D12: {=IFERROR(SMALL(IF('射擊表'!$A$2:$A$500=5,'射擊表'!$B$2:$B$500),11),NA())} | E12: {=IFERROR(INDEX('射擊表'!$C$2:$C$500,MATCH(1,('射擊表'!$A$2:$A$500=5)*('射擊表'!$B$2:$B$500=D12),0)),NA())} | F12: {=IFERROR(INDEX(IF('射擊表'!$E$2:$E$500="us",ABS('射擊表'!$D$2:$D$500-1500)/5,'射擊表'!$D$2:$D$500),MATCH(1,('射擊表'!$A$2:$A$500=5)*('射擊表'!$B$2:$B$500=D12),0)),NA())} | G12: {=IFERROR(SMALL(IF('射擊表'!$A$2:$A$500=6,'射擊表'!$B$2:$B$500),11),NA())} | H12: {=IFERROR(INDEX('射擊表'!$C$2:$C$500,MATCH(1,('射擊表'!$A$2:$A$500=6)*('射擊表'!$B$2:$B$500=G12),0)),NA())} | I12: {=IFERROR(INDEX(IF('射擊表'!$E$2:$E$500="us",ABS('射擊表'!$D$2:$D$500-1500)/5,'射擊表'!$D$2:$D$500),MATCH(1,('射擊表'!$A$2:$A$500=6)*('射擊表'!$B$2:$B$500=G12),0)),NA())}
A13: {=IFERROR(SMALL(IF('射擊表'!$A$2:$A$500=4,'射擊表'!$B$2:$B$500),12),NA())} | B13: {=IFERROR(INDEX('射擊表'!$C$2:$C$500,MATCH(1,('射擊表'!$A$2:$A$500=4)*('射擊表'!$B$2:$B$500=A13),0)),NA())} | C13: {=IFERROR(INDEX(IF('射擊表'!$E$2:$E$500="us",ABS('射擊表'!$D$2:$D$500-1500)/5,'射擊表'!$D$2:$D$500),MATCH(1,('射擊表'!$A$2:$A$500=4)*('射擊表'!$B$2:$B$500=A13),0)),NA())} | D13: {=IFERROR(SMALL(IF('射擊表'!$A$2:$A$500=5,'射擊表'!$B$2:$B$500),12),NA())} | E13: {=IFERROR(INDEX('射擊表'!$C$2:$C$500,MATCH(1,('射擊表'!$A$2:$A$500=5)*('射擊表'!$B$2:$B$500=D13),0)),NA())} | F13: {=IFERROR(INDEX(IF('射擊表'!$E$2:$E$500="us",ABS('射擊表'!$D$2:$D$500-1500)/5,'射擊表'!$D$2:$D$500),MATCH(1,('射擊表'!$A$2:$A$500=5)*('射擊表'!$B$2:$B$500=D13),0)),NA())} | G13: {=IFERROR(SMALL(IF('射擊表'!$A$2:$A$500=6,'射擊表'!$B$2:$B$500),12),NA())} | H13: {=IFERROR(INDEX('射擊表'!$C$2:$C$500,MATCH(1,('射擊表'!$A$2:$A$500=6)*('射擊表'!$B$2:$B$500=G13),0)),NA())} | I13: {=IFERROR(INDEX(IF('射擊表'!$E$2:$E$500="us",ABS('射擊表'!$D$2:$D$500-1500)/5,'射擊表'!$D$2:$D$500),MATCH(1,('射擊表'!$A$2:$A$500=6)*('射擊表'!$B$2:$B$500=G13),0)),NA())}
A14: {=IFERROR(SMALL(IF('射擊表'!$A$2:$A$500=4,'射擊表'!$B$2:$B$500),13),NA())} | B14: {=IFERROR(INDEX('射擊表'!$C$2:$C$500,MATCH(1,('射擊表'!$A$2:$A$500=4)*('射擊表'!$B$2:$B$500=A14),0)),NA())} | C14: {=IFERROR(INDEX(IF('射擊表'!$E$2:$E$500="us",ABS('射擊表'!$D$2:$D$500-1500)/5,'射擊表'!$D$2:$D$500),MATCH(1,('射擊表'!$A$2:$A$500=4)*('射擊表'!$B$2:$B$500=A14),0)),NA())} | D14: {=IFERROR(SMALL(IF('射擊表'!$A$2:$A$500=5,'射擊表'!$B$2:$B$500),13),NA())} | E14: {=IFERROR(INDEX('射擊表'!$C$2:$C$500,MATCH(1,('射擊表'!$A$2:$A$500=5)*('射擊表'!$B$2:$B$500=D14),0)),NA())} | F14: {=IFERROR(INDEX(IF('射擊表'!$E$2:$E$500="us",ABS('射擊表'!$D$2:$D$500-1500)/5,'射擊表'!$D$2:$D$500),MATCH(1,('射擊表'!$A$2:$A$500=5)*('射擊表'!$B$2:$B$500=D14),0)),NA())} | G14: {=IFERROR(SMALL(IF('射擊表'!$A$2:$A$500=6,'射擊表'!$B$2:$B$500),13),NA())} | H14: {=IFERROR(INDEX('射擊表'!$C$2:$C$500,MATCH(1,('射擊表'!$A$2:$A$500=6)*('射擊表'!$B$2:$B$500=G14),0)),NA())} | I14: {=IFERROR(INDEX(IF('射擊表'!$E$2:$E$500="us",ABS('射擊表'!$D$2:$D$500-1500)/5,'射擊表'!$D$2:$D$500),MATCH(1,('射擊表'!$A$2:$A$500=6)*('射擊表'!$B$2:$B$500=G14),0)),NA())}
A15: {=IFERROR(SMALL(IF('射擊表'!$A$2:$A$500=4,'射擊表'!$B$2:$B$500),14),NA())} | B15: {=IFERROR(INDEX('射擊表'!$C$2:$C$500,MATCH(1,('射擊表'!$A$2:$A$500=4)*('射擊表'!$B$2:$B$500=A15),0)),NA())} | C15: {=IFERROR(INDEX(IF('射擊表'!$E$2:$E$500="us",ABS('射擊表'!$D$2:$D$500-1500)/5,'射擊表'!$D$2:$D$500),MATCH(1,('射擊表'!$A$2:$A$500=4)*('射擊表'!$B$2:$B$500=A15),0)),NA())} | D15: {=IFERROR(SMALL(IF('射擊表'!$A$2:$A$500=5,'射擊表'!$B$2:$B$500),14),NA())} | E15: {=IFERROR(INDEX('射擊表'!$C$2:$C$500,MATCH(1,('射擊表'!$A$2:$A$500=5)*('射擊表'!$B$2:$B$500=D15),0)),NA())} | F15: {=IFERROR(INDEX(IF('射擊表'!$E$2:$E$500="us",ABS('射擊表'!$D$2:$D$500-1500)/5,'射擊表'!$D$2:$D$500),MATCH(1,('射擊表'!$A$2:$A$500=5)*('射擊表'!$B$2:$B$500=D15),0)),NA())} | G15: {=IFERROR(SMALL(IF('射擊表'!$A$2:$A$500=6,'射擊表'!$B$2:$B$500),14),NA())} | H15: {=IFERROR(INDEX('射擊表'!$C$2:$C$500,MATCH(1,('射擊表'!$A$2:$A$500=6)*('射擊表'!$B$2:$B$500=G15),0)),NA())} | I15: {=IFERROR(INDEX(IF('射擊表'!$E$2:$E$500="us",ABS('射擊表'!$D$2:$D$500-1500)/5,'射擊表'!$D$2:$D$500),MATCH(1,('射擊表'!$A$2:$A$500=6)*('射擊表'!$B$2:$B$500=G15),0)),NA())}
A16: {=IFERROR(SMALL(IF('射擊表'!$A$2:$A$500=4,'射擊表'!$B$2:$B$500),15),NA())} | B16: {=IFERROR(INDEX('射擊表'!$C$2:$C$500,MATCH(1,('射擊表'!$A$2:$A$500=4)*('射擊表'!$B$2:$B$500=A16),0)),NA())} | C16: {=IFERROR(INDEX(IF('射擊表'!$E$2:$E$500="us",ABS('射擊表'!$D$2:$D$500-1500)/5,'射擊表'!$D$2:$D$500),MATCH(1,('射擊表'!$A$2:$A$500=4)*('射擊表'!$B$2:$B$500=A16),0)),NA())} | D16: {=IFERROR(SMALL(IF('射擊表'!$A$2:$A$500=5,'射擊表'!$B$2:$B$500),15),NA())} | E16: {=IFERROR(INDEX('射擊表'!$C$2:$C$500,MATCH(1,('射擊表'!$A$2:$A$500=5)*('射擊表'!$B$2:$B$500=D16),0)),NA())} | F16: {=IFERROR(INDEX(IF('射擊表'!$E$2:$E$500="us",ABS('射擊表'!$D$2:$D$500-1500)/5,'射擊表'!$D$2:$D$500),MATCH(1,('射擊表'!$A$2:$A$500=5)*('射擊表'!$B$2:$B$500=D16),0)),NA())} | G16: {=IFERROR(SMALL(IF('射擊表'!$A$2:$A$500=6,'射擊表'!$B$2:$B$500),15),NA())} | H16: {=IFERROR(INDEX('射擊表'!$C$2:$C$500,MATCH(1,('射擊表'!$A$2:$A$500=6)*('射擊表'!$B$2:$B$500=G16),0)),NA())} | I16: {=IFERROR(INDEX(IF('射擊表'!$E$2:$E$500="us",ABS('射擊表'!$D$2:$D$500-1500)/5,'射擊表'!$D$2:$D$500),MATCH(1,('射擊表'!$A$2:$A$500=6)*('射擊表'!$B$2:$B$500=G16),0)),NA())}
A17: {=IFERROR(SMALL(IF('射擊表'!$A$2:$A$500=4,'射擊表'!$B$2:$B$500),16),NA())} | B17: {=IFERROR(INDEX('射擊表'!$C$2:$C$500,MATCH(1,('射擊表'!$A$2:$A$500=4)*('射擊表'!$B$2:$B$500=A17),0)),NA())} | C17: {=IFERROR(INDEX(IF('射擊表'!$E$2:$E$500="us",ABS('射擊表'!$D$2:$D$500-1500)/5,'射擊表'!$D$2:$D$500),MATCH(1,('射擊表'!$A$2:$A$500=4)*('射擊表'!$B$2:$B$500=A17),0)),NA())} | D17: {=IFERROR(SMALL(IF('射擊表'!$A$2:$A$500=5,'射擊表'!$B$2:$B$500),16),NA())} | E17: {=IFERROR(INDEX('射擊表'!$C$2:$C$500,MATCH(1,('射擊表'!$A$2:$A$500=5)*('射擊表'!$B$2:$B$500=D17),0)),NA())} | F17: {=IFERROR(INDEX(IF('射擊表'!$E$2:$E$500="us",ABS('射擊表'!$D$2:$D$500-1500)/5,'射擊表'!$D$2:$D$500),MATCH(1,('射擊表'!$A$2:$A$500=5)*('射擊表'!$B$2:$B$500=D17),0)),NA())} | G17: {=IFERROR(SMALL(IF('射擊表'!$A$2:$A$500=6,'射擊表'!$B$2:$B$500),16),NA())} | H17: {=IFERROR(INDEX('射擊表'!$C$2:$C$500,MATCH(1,('射擊表'!$A$2:$A$500=6)*('射擊表'!$B$2:$B$500=G17),0)),NA())} | I17: {=IFERROR(INDEX(IF('射擊表'!$E$2:$E$500="us",ABS('射擊表'!$D$2:$D$500-1500)/5,'射擊表'!$D$2:$D$500),MATCH(1,('射擊表'!$A$2:$A$500=6)*('射擊表'!$B$2:$B$500=G17),0)),NA())}
A18: {=IFERROR(SMALL(IF('射擊表'!$A$2:$A$500=4,'射擊表'!$B$2:$B$500),17),NA())} | B18: {=IFERROR(INDEX('射擊表'!$C$2:$C$500,MATCH(1,('射擊表'!$A$2:$A$500=4)*('射擊表'!$B$2:$B$500=A18),0)),NA())} | C18: {=IFERROR(INDEX(IF('射擊表'!$E$2:$E$500="us",ABS('射擊表'!$D$2:$D$500-1500)/5,'射擊表'!$D$2:$D$500),MATCH(1,('射擊表'!$A$2:$A$500=4)*('射擊表'!$B$2:$B$500=A18),0)),NA())} | D18: {=IFERROR(SMALL(IF('射擊表'!$A$2:$A$500=5,'射擊表'!$B$2:$B$500),17),NA())} | E18: {=IFERROR(INDEX('射擊表'!$C$2:$C$500,MATCH(1,('射擊表'!$A$2:$A$500=5)*('射擊表'!$B$2:$B$500=D18),0)),NA())} | F18: {=IFERROR(INDEX(IF('射擊表'!$E$2:$E$500="us",ABS('射擊表'!$D$2:$D$500-1500)/5,'射擊表'!$D$2:$D$500),MATCH(1,('射擊表'!$A$2:$A$500=5)*('射擊表'!$B$2:$B$500=D18),0)),NA())} | G18: {=IFERROR(SMALL(IF('射擊表'!$A$2:$A$500=6,'射擊表'!$B$2:$B$500),17),NA())} | H18: {=IFERROR(INDEX('射擊表'!$C$2:$C$500,MATCH(1,('射擊表'!$A$2:$A$500=6)*('射擊表'!$B$2:$B$500=G18),0)),NA())} | I18: {=IFERROR(INDEX(IF('射擊表'!$E$2:$E$500="us",ABS('射擊表'!$D$2:$D$500-1500)/5,'射擊表'!$D$2:$D$500),MATCH(1,('射擊表'!$A$2:$A$500=6)*('射擊表'!$B$2:$B$500=G18),0)),NA())}
A19: {=IFERROR(SMALL(IF('射擊表'!$A$2:$A$500=4,'射擊表'!$B$2:$B$500),18),NA())} | B19: {=IFERROR(INDEX('射擊表'!$C$2:$C$500,MATCH(1,('射擊表'!$A$2:$A$500=4)*('射擊表'!$B$2:$B$500=A19),0)),NA())} | C19: {=IFERROR(INDEX(IF('射擊表'!$E$2:$E$500="us",ABS('射擊表'!$D$2:$D$500-1500)/5,'射擊表'!$D$2:$D$500),MATCH(1,('射擊表'!$A$2:$A$500=4)*('射擊表'!$B$2:$B$500=A19),0)),NA())} | D19: {=IFERROR(SMALL(IF('射擊表'!$A$2:$A$500=5,'射擊表'!$B$2:$B$500),18),NA())} | E19: {=IFERROR(INDEX('射擊表'!$C$2:$C$500,MATCH(1,('射擊表'!$A$2:$A$500=5)*('射擊表'!$B$2:$B$500=D19),0)),NA())} | F19: {=IFERROR(INDEX(IF('射擊表'!$E$2:$E$500="us",ABS('射擊表'!$D$2:$D$500-1500)/5,'射擊表'!$D$2:$D$500),MATCH(1,('射擊表'!$A$2:$A$500=5)*('射擊表'!$B$2:$B$500=D19),0)),NA())} | G19: {=IFERROR(SMALL(IF('射擊表'!$A$2:$A$500=6,'射擊表'!$B$2:$B$500),18),NA())} | H19: {=IFERROR(INDEX('射擊表'!$C$2:$C$500,MATCH(1,('射擊表'!$A$2:$A$500=6)*('射擊表'!$B$2:$B$500=G19),0)),NA())} | I19: {=IFERROR(INDEX(IF('射擊表'!$E$2:$E$500="us",ABS('射擊表'!$D$2:$D$500-1500)/5,'射擊表'!$D$2:$D$500),MATCH(1,('射擊表'!$A$2:$A$500=6)*('射擊表'!$B$2:$B$500=G19),0)),NA())}
A20: {=IFERROR(SMALL(IF('射擊表'!$A$2:$A$500=4,'射擊表'!$B$2:$B$500),19),NA())} | B20: {=IFERROR(INDEX('射擊表'!$C$2:$C$500,MATCH(1,('射擊表'!$A$2:$A$500=4)*('射擊表'!$B$2:$B$500=A20),0)),NA())} | C20: {=IFERROR(INDEX(IF('射擊表'!$E$2:$E$500="us",ABS('射擊表'!$D$2:$D$500-1500)/5,'射擊表'!$D$2:$D$500),MATCH(1,('射擊表'!$A$2:$A$500=4)*('射擊表'!$B$2:$B$500=A20),0)),NA())} | D20: {=IFERROR(SMALL(IF('射擊表'!$A$2:$A$500=5,'射擊表'!$B$2:$B$500),19),NA())} | E20: {=IFERROR(INDEX('射擊表'!$C$2:$C$500,MATCH(1,('射擊表'!$A$2:$A$500=5)*('射擊表'!$B$2:$B$500=D20),0)),NA())} | F20: {=IFERROR(INDEX(IF('射擊表'!$E$2:$E$500="us",ABS('射擊表'!$D$2:$D$500-1500)/5,'射擊表'!$D$2:$D$500),MATCH(1,('射擊表'!$A$2:$A$500=5)*('射擊表'!$B$2:$B$500=D20),0)),NA())} | G20: {=IFERROR(SMALL(IF('射擊表'!$A$2:$A$500=6,'射擊表'!$B$2:$B$500),19),NA())} | H20: {=IFERROR(INDEX('射擊表'!$C$2:$C$500,MATCH(1,('射擊表'!$A$2:$A$500=6)*('射擊表'!$B$2:$B$500=G20),0)),NA())} | I20: {=IFERROR(INDEX(IF('射擊表'!$E$2:$E$500="us",ABS('射擊表'!$D$2:$D$500-1500)/5,'射擊表'!$D$2:$D$500),MATCH(1,('射擊表'!$A$2:$A$500=6)*('射擊表'!$B$2:$B$500=G20),0)),NA())}
A21: {=IFERROR(SMALL(IF('射擊表'!$A$2:$A$500=4,'射擊表'!$B$2:$B$500),20),NA())} | B21: {=IFERROR(INDEX('射擊表'!$C$2:$C$500,MATCH(1,('射擊表'!$A$2:$A$500=4)*('射擊表'!$B$2:$B$500=A21),0)),NA())} | C21: {=IFERROR(INDEX(IF('射擊表'!$E$2:$E$500="us",ABS('射擊表'!$D$2:$D$500-1500)/5,'射擊表'!$D$2:$D$500),MATCH(1,('射擊表'!$A$2:$A$500=4)*('射擊表'!$B$2:$B$500=A21),0)),NA())} | D21: {=IFERROR(SMALL(IF('射擊表'!$A$2:$A$500=5,'射擊表'!$B$2:$B$500),20),NA())} | E21: {=IFERROR(INDEX('射擊表'!$C$2:$C$500,MATCH(1,('射擊表'!$A$2:$A$500=5)*('射擊表'!$B$2:$B$500=D21),0)),NA())} | F21: {=IFERROR(INDEX(IF('射擊表'!$E$2:$E$500="us",ABS('射擊表'!$D$2:$D$500-1500)/5,'射擊表'!$D$2:$D$500),MATCH(1,('射擊表'!$A$2:$A$500=5)*('射擊表'!$B$2:$B$500=D21),0)),NA())} | G21: {=IFERROR(SMALL(IF('射擊表'!$A$2:$A$500=6,'射擊表'!$B$2:$B$500),20),NA())} | H21: {=IFERROR(INDEX('射擊表'!$C$2:$C$500,MATCH(1,('射擊表'!$A$2:$A$500=6)*('射擊表'!$B$2:$B$500=G21),0)),NA())} | I21: {=IFERROR(INDEX(IF('射擊表'!$E$2:$E$500="us",ABS('射擊表'!$D$2:$D$500-1500)/5,'射擊表'!$D$2:$D$500),MATCH(1,('射擊表'!$A$2:$A$500=6)*('射擊表'!$B$2:$B$500=G21),0)),NA())}
A22: {=IFERROR(SMALL(IF('射擊表'!$A$2:$A$500=4,'射擊表'!$B$2:$B$500),21),NA())} | B22: {=IFERROR(INDEX('射擊表'!$C$2:$C$500,MATCH(1,('射擊表'!$A$2:$A$500=4)*('射擊表'!$B$2:$B$500=A22),0)),NA())} | C22: {=IFERROR(INDEX(IF('射擊表'!$E$2:$E$500="us",ABS('射擊表'!$D$2:$D$500-1500)/5,'射擊表'!$D$2:$D$500),MATCH(1,('射擊表'!$A$2:$A$500=4)*('射擊表'!$B$2:$B$500=A22),0)),NA())} | D22: {=IFERROR(SMALL(IF('射擊表'!$A$2:$A$500=5,'射擊表'!$B$2:$B$500),21),NA())} | E22: {=IFERROR(INDEX('射擊表'!$C$2:$C$500,MATCH(1,('射擊表'!$A$2:$A$500=5)*('射擊表'!$B$2:$B$500=D22),0)),NA())} | F22: {=IFERROR(INDEX(IF('射擊表'!$E$2:$E$500="us",ABS('射擊表'!$D$2:$D$500-1500)/5,'射擊表'!$D$2:$D$500),MATCH(1,('射擊表'!$A$2:$A$500=5)*('射擊表'!$B$2:$B$500=D22),0)),NA())} | G22: {=IFERROR(SMALL(IF('射擊表'!$A$2:$A$500=6,'射擊表'!$B$2:$B$500),21),NA())} | H22: {=IFERROR(INDEX('射擊表'!$C$2:$C$500,MATCH(1,('射擊表'!$A$2:$A$500=6)*('射擊表'!$B$2:$B$500=G22),0)),NA())} | I22: {=IFERROR(INDEX(IF('射擊表'!$E$2:$E$500="us",ABS('射擊表'!$D$2:$D$500-1500)/5,'射擊表'!$D$2:$D$500),MATCH(1,('射擊表'!$A$2:$A$500=6)*('射擊表'!$B$2:$B$500=G22),0)),NA())}
A23: {=IFERROR(SMALL(IF('射擊表'!$A$2:$A$500=4,'射擊表'!$B$2:$B$500),22),NA())} | B23: {=IFERROR(INDEX('射擊表'!$C$2:$C$500,MATCH(1,('射擊表'!$A$2:$A$500=4)*('射擊表'!$B$2:$B$500=A23),0)),NA())} | C23: {=IFERROR(INDEX(IF('射擊表'!$E$2:$E$500="us",ABS('射擊表'!$D$2:$D$500-1500)/5,'射擊表'!$D$2:$D$500),MATCH(1,('射擊表'!$A$2:$A$500=4)*('射擊表'!$B$2:$B$500=A23),0)),NA())} | D23: {=IFERROR(SMALL(IF('射擊表'!$A$2:$A$500=5,'射擊表'!$B$2:$B$500),22),NA())} | E23: {=IFERROR(INDEX('射擊表'!$C$2:$C$500,MATCH(1,('射擊表'!$A$2:$A$500=5)*('射擊表'!$B$2:$B$500=D23),0)),NA())} | F23: {=IFERROR(INDEX(IF('射擊表'!$E$2:$E$500="us",ABS('射擊表'!$D$2:$D$500-1500)/5,'射擊表'!$D$2:$D$500),MATCH(1,('射擊表'!$A$2:$A$500=5)*('射擊表'!$B$2:$B$500=D23),0)),NA())} | G23: {=IFERROR(SMALL(IF('射擊表'!$A$2:$A$500=6,'射擊表'!$B$2:$B$500),22),NA())} | H23: {=IFERROR(INDEX('射擊表'!$C$2:$C$500,MATCH(1,('射擊表'!$A$2:$A$500=6)*('射擊表'!$B$2:$B$500=G23),0)),NA())} | I23: {=IFERROR(INDEX(IF('射擊表'!$E$2:$E$500="us",ABS('射擊表'!$D$2:$D$500-1500)/5,'射擊表'!$D$2:$D$500),MATCH(1,('射擊表'!$A$2:$A$500=6)*('射擊表'!$B$2:$B$500=G23),0)),NA())}
A24: {=IFERROR(SMALL(IF('射擊表'!$A$2:$A$500=4,'射擊表'!$B$2:$B$500),23),NA())} | B24: {=IFERROR(INDEX('射擊表'!$C$2:$C$500,MATCH(1,('射擊表'!$A$2:$A$500=4)*('射擊表'!$B$2:$B$500=A24),0)),NA())} | C24: {=IFERROR(INDEX(IF('射擊表'!$E$2:$E$500="us",ABS('射擊表'!$D$2:$D$500-1500)/5,'射擊表'!$D$2:$D$500),MATCH(1,('射擊表'!$A$2:$A$500=4)*('射擊表'!$B$2:$B$500=A24),0)),NA())} | D24: {=IFERROR(SMALL(IF('射擊表'!$A$2:$A$500=5,'射擊表'!$B$2:$B$500),23),NA())} | E24: {=IFERROR(INDEX('射擊表'!$C$2:$C$500,MATCH(1,('射擊表'!$A$2:$A$500=5)*('射擊表'!$B$2:$B$500=D24),0)),NA())} | F24: {=IFERROR(INDEX(IF('射擊表'!$E$2:$E$500="us",ABS('射擊表'!$D$2:$D$500-1500)/5,'射擊表'!$D$2:$D$500),MATCH(1,('射擊表'!$A$2:$A$500=5)*('射擊表'!$B$2:$B$500=D24),0)),NA())} | G24: {=IFERROR(SMALL(IF('射擊表'!$A$2:$A$500=6,'射擊表'!$B$2:$B$500),23),NA())} | H24: {=IFERROR(INDEX('射擊表'!$C$2:$C$500,MATCH(1,('射擊表'!$A$2:$A$500=6)*('射擊表'!$B$2:$B$500=G24),0)),NA())} | I24: {=IFERROR(INDEX(IF('射擊表'!$E$2:$E$500="us",ABS('射擊表'!$D$2:$D$500-1500)/5,'射擊表'!$D$2:$D$500),MATCH(1,('射擊表'!$A$2:$A$500=6)*('射擊表'!$B$2:$B$500=G24),0)),NA())}
A25: {=IFERROR(SMALL(IF('射擊表'!$A$2:$A$500=4,'射擊表'!$B$2:$B$500),24),NA())} | B25: {=IFERROR(INDEX('射擊表'!$C$2:$C$500,MATCH(1,('射擊表'!$A$2:$A$500=4)*('射擊表'!$B$2:$B$500=A25),0)),NA())} | C25: {=IFERROR(INDEX(IF('射擊表'!$E$2:$E$500="us",ABS('射擊表'!$D$2:$D$500-1500)/5,'射擊表'!$D$2:$D$500),MATCH(1,('射擊表'!$A$2:$A$500=4)*('射擊表'!$B$2:$B$500=A25),0)),NA())} | D25: {=IFERROR(SMALL(IF('射擊表'!$A$2:$A$500=5,'射擊表'!$B$2:$B$500),24),NA())} | E25: {=IFERROR(INDEX('射擊表'!$C$2:$C$500,MATCH(1,('射擊表'!$A$2:$A$500=5)*('射擊表'!$B$2:$B$500=D25),0)),NA())} | F25: {=IFERROR(INDEX(IF('射擊表'!$E$2:$E$500="us",ABS('射擊表'!$D$2:$D$500-1500)/5,'射擊表'!$D$2:$D$500),MATCH(1,('射擊表'!$A$2:$A$500=5)*('射擊表'!$B$2:$B$500=D25),0)),NA())} | G25: {=IFERROR(SMALL(IF('射擊表'!$A$2:$A$500=6,'射擊表'!$B$2:$B$500),24),NA())} | H25: {=IFERROR(INDEX('射擊表'!$C$2:$C$500,MATCH(1,('射擊表'!$A$2:$A$500=6)*('射擊表'!$B$2:$B$500=G25),0)),NA())} | I25: {=IFERROR(INDEX(IF('射擊表'!$E$2:$E$500="us",ABS('射擊表'!$D$2:$D$500-1500)/5,'射擊表'!$D$2:$D$500),MATCH(1,('射擊表'!$A$2:$A$500=6)*('射擊表'!$B$2:$B$500=G25),0)),NA())}
A26: {=IFERROR(SMALL(IF('射擊表'!$A$2:$A$500=4,'射擊表'!$B$2:$B$500),25),NA())} | B26: {=IFERROR(INDEX('射擊表'!$C$2:$C$500,MATCH(1,('射擊表'!$A$2:$A$500=4)*('射擊表'!$B$2:$B$500=A26),0)),NA())} | C26: {=IFERROR(INDEX(IF('射擊表'!$E$2:$E$500="us",ABS('射擊表'!$D$2:$D$500-1500)/5,'射擊表'!$D$2:$D$500),MATCH(1,('射擊表'!$A$2:$A$500=4)*('射擊表'!$B$2:$B$500=A26),0)),NA())} | D26: {=IFERROR(SMALL(IF('射擊表'!$A$2:$A$500=5,'射擊表'!$B$2:$B$500),25),NA())} | E26: {=IFERROR(INDEX('射擊表'!$C$2:$C$500,MATCH(1,('射擊表'!$A$2:$A$500=5)*('射擊表'!$B$2:$B$500=D26),0)),NA())} | F26: {=IFERROR(INDEX(IF('射擊表'!$E$2:$E$500="us",ABS('射擊表'!$D$2:$D$500-1500)/5,'射擊表'!$D$2:$D$500),MATCH(1,('射擊表'!$A$2:$A$500=5)*('射擊表'!$B$2:$B$500=D26),0)),NA())} | G26: {=IFERROR(SMALL(IF('射擊表'!$A$2:$A$500=6,'射擊表'!$B$2:$B$500),25),NA())} | H26: {=IFERROR(INDEX('射擊表'!$C$2:$C$500,MATCH(1,('射擊表'!$A$2:$A$500=6)*('射擊表'!$B$2:$B$500=G26),0)),NA())} | I26: {=IFERROR(INDEX(IF('射擊表'!$E$2:$E$500="us",ABS('射擊表'!$D$2:$D$500-1500)/5,'射擊表'!$D$2:$D$500),MATCH(1,('射擊表'!$A$2:$A$500=6)*('射擊表'!$B$2:$B$500=G26),0)),NA())}
A27: {=IFERROR(SMALL(IF('射擊表'!$A$2:$A$500=4,'射擊表'!$B$2:$B$500),26),NA())} | B27: {=IFERROR(INDEX('射擊表'!$C$2:$C$500,MATCH(1,('射擊表'!$A$2:$A$500=4)*('射擊表'!$B$2:$B$500=A27),0)),NA())} | C27: {=IFERROR(INDEX(IF('射擊表'!$E$2:$E$500="us",ABS('射擊表'!$D$2:$D$500-1500)/5,'射擊表'!$D$2:$D$500),MATCH(1,('射擊表'!$A$2:$A$500=4)*('射擊表'!$B$2:$B$500=A27),0)),NA())} | D27: {=IFERROR(SMALL(IF('射擊表'!$A$2:$A$500=5,'射擊表'!$B$2:$B$500),26),NA())} | E27: {=IFERROR(INDEX('射擊表'!$C$2:$C$500,MATCH(1,('射擊表'!$A$2:$A$500=5)*('射擊表'!$B$2:$B$500=D27),0)),NA())} | F27: {=IFERROR(INDEX(IF('射擊表'!$E$2:$E$500="us",ABS('射擊表'!$D$2:$D$500-1500)/5,'射擊表'!$D$2:$D$500),MATCH(1,('射擊表'!$A$2:$A$500=5)*('射擊表'!$B$2:$B$500=D27),0)),NA())} | G27: {=IFERROR(SMALL(IF('射擊表'!$A$2:$A$500=6,'射擊表'!$B$2:$B$500),26),NA())} | H27: {=IFERROR(INDEX('射擊表'!$C$2:$C$500,MATCH(1,('射擊表'!$A$2:$A$500=6)*('射擊表'!$B$2:$B$500=G27),0)),NA())} | I27: {=IFERROR(INDEX(IF('射擊表'!$E$2:$E$500="us",ABS('射擊表'!$D$2:$D$500-1500)/5,'射擊表'!$D$2:$D$500),MATCH(1,('射擊表'!$A$2:$A$500=6)*('射擊表'!$B$2:$B$500=G27),0)),NA())}
A28: {=IFERROR(SMALL(IF('射擊表'!$A$2:$A$500=4,'射擊表'!$B$2:$B$500),27),NA())} | B28: {=IFERROR(INDEX('射擊表'!$C$2:$C$500,MATCH(1,('射擊表'!$A$2:$A$500=4)*('射擊表'!$B$2:$B$500=A28),0)),NA())} | C28: {=IFERROR(INDEX(IF('射擊表'!$E$2:$E$500="us",ABS('射擊表'!$D$2:$D$500-1500)/5,'射擊表'!$D$2:$D$500),MATCH(1,('射擊表'!$A$2:$A$500=4)*('射擊表'!$B$2:$B$500=A28),0)),NA())} | D28: {=IFERROR(SMALL(IF('射擊表'!$A$2:$A$500=5,'射擊表'!$B$2:$B$500),27),NA())} | E28: {=IFERROR(INDEX('射擊表'!$C$2:$C$500,MATCH(1,('射擊表'!$A$2:$A$500=5)*('射擊表'!$B$2:$B$500=D28),0)),NA())} | F28: {=IFERROR(INDEX(IF('射擊表'!$E$2:$E$500="us",ABS('射擊表'!$D$2:$D$500-1500)/5,'射擊表'!$D$2:$D$500),MATCH(1,('射擊表'!$A$2:$A$500=5)*('射擊表'!$B$2:$B$500=D28),0)),NA())} | G28: {=IFERROR(SMALL(IF('射擊表'!$A$2:$A$500=6,'射擊表'!$B$2:$B$500),27),NA())} | H28: {=IFERROR(INDEX('射擊表'!$C$2:$C$500,MATCH(1,('射擊表'!$A$2:$A$500=6)*('射擊表'!$B$2:$B$500=G28),0)),NA())} | I28: {=IFERROR(INDEX(IF('射擊表'!$E$2:$E$500="us",ABS('射擊表'!$D$2:$D$500-1500)/5,'射擊表'!$D$2:$D$500),MATCH(1,('射擊表'!$A$2:$A$500=6)*('射擊表'!$B$2:$B$500=G28),0)),NA())}
A29: {=IFERROR(SMALL(IF('射擊表'!$A$2:$A$500=4,'射擊表'!$B$2:$B$500),28),NA())} | B29: {=IFERROR(INDEX('射擊表'!$C$2:$C$500,MATCH(1,('射擊表'!$A$2:$A$500=4)*('射擊表'!$B$2:$B$500=A29),0)),NA())} | C29: {=IFERROR(INDEX(IF('射擊表'!$E$2:$E$500="us",ABS('射擊表'!$D$2:$D$500-1500)/5,'射擊表'!$D$2:$D$500),MATCH(1,('射擊表'!$A$2:$A$500=4)*('射擊表'!$B$2:$B$500=A29),0)),NA())} | D29: {=IFERROR(SMALL(IF('射擊表'!$A$2:$A$500=5,'射擊表'!$B$2:$B$500),28),NA())} | E29: {=IFERROR(INDEX('射擊表'!$C$2:$C$500,MATCH(1,('射擊表'!$A$2:$A$500=5)*('射擊表'!$B$2:$B$500=D29),0)),NA())} | F29: {=IFERROR(INDEX(IF('射擊表'!$E$2:$E$500="us",ABS('射擊表'!$D$2:$D$500-1500)/5,'射擊表'!$D$2:$D$500),MATCH(1,('射擊表'!$A$2:$A$500=5)*('射擊表'!$B$2:$B$500=D29),0)),NA())} | G29: {=IFERROR(SMALL(IF('射擊表'!$A$2:$A$500=6,'射擊表'!$B$2:$B$500),28),NA())} | H29: {=IFERROR(INDEX('射擊表'!$C$2:$C$500,MATCH(1,('射擊表'!$A$2:$A$500=6)*('射擊表'!$B$2:$B$500=G29),0)),NA())} | I29: {=IFERROR(INDEX(IF('射擊表'!$E$2:$E$500="us",ABS('射擊表'!$D$2:$D$500-1500)/5,'射擊表'!$D$2:$D$500),MATCH(1,('射擊表'!$A$2:$A$500=6)*('射擊表'!$B$2:$B$500=G29),0)),NA())}
A30: {=IFERROR(SMALL(IF('射擊表'!$A$2:$A$500=4,'射擊表'!$B$2:$B$500),29),NA())} | B30: {=IFERROR(INDEX('射擊表'!$C$2:$C$500,MATCH(1,('射擊表'!$A$2:$A$500=4)*('射擊表'!$B$2:$B$500=A30),0)),NA())} | C30: {=IFERROR(INDEX(IF('射擊表'!$E$2:$E$500="us",ABS('射擊表'!$D$2:$D$500-1500)/5,'射擊表'!$D$2:$D$500),MATCH(1,('射擊表'!$A$2:$A$500=4)*('射擊表'!$B$2:$B$500=A30),0)),NA())} | D30: {=IFERROR(SMALL(IF('射擊表'!$A$2:$A$500=5,'射擊表'!$B$2:$B$500),29),NA())} | E30: {=IFERROR(INDEX('射擊表'!$C$2:$C$500,MATCH(1,('射擊表'!$A$2:$A$500=5)*('射擊表'!$B$2:$B$500=D30),0)),NA())} | F30: {=IFERROR(INDEX(IF('射擊表'!$E$2:$E$500="us",ABS('射擊表'!$D$2:$D$500-1500)/5,'射擊表'!$D$2:$D$500),MATCH(1,('射擊表'!$A$2:$A$500=5)*('射擊表'!$B$2:$B$500=D30),0)),NA())} | G30: {=IFERROR(SMALL(IF('射擊表'!$A$2:$A$500=6,'射擊表'!$B$2:$B$500),29),NA())} | H30: {=IFERROR(INDEX('射擊表'!$C$2:$C$500,MATCH(1,('射擊表'!$A$2:$A$500=6)*('射擊表'!$B$2:$B$500=G30),0)),NA())} | I30: {=IFERROR(INDEX(IF('射擊表'!$E$2:$E$500="us",ABS('射擊表'!$D$2:$D$500-1500)/5,'射擊表'!$D$2:$D$500),MATCH(1,('射擊表'!$A$2:$A$500=6)*('射擊表'!$B$2:$B$500=G30),0)),NA())}
A31: {=IFERROR(SMALL(IF('射擊表'!$A$2:$A$500=4,'射擊表'!$B$2:$B$500),30),NA())} | B31: {=IFERROR(INDEX('射擊表'!$C$2:$C$500,MATCH(1,('射擊表'!$A$2:$A$500=4)*('射擊表'!$B$2:$B$500=A31),0)),NA())} | C31: {=IFERROR(INDEX(IF('射擊表'!$E$2:$E$500="us",ABS('射擊表'!$D$2:$D$500-1500)/5,'射擊表'!$D$2:$D$500),MATCH(1,('射擊表'!$A$2:$A$500=4)*('射擊表'!$B$2:$B$500=A31),0)),NA())} | D31: {=IFERROR(SMALL(IF('射擊表'!$A$2:$A$500=5,'射擊表'!$B$2:$B$500),30),NA())} | E31: {=IFERROR(INDEX('射擊表'!$C$2:$C$500,MATCH(1,('射擊表'!$A$2:$A$500=5)*('射擊表'!$B$2:$B$500=D31),0)),NA())} | F31: {=IFERROR(INDEX(IF('射擊表'!$E$2:$E$500="us",ABS('射擊表'!$D$2:$D$500-1500)/5,'射擊表'!$D$2:$D$500),MATCH(1,('射擊表'!$A$2:$A$500=5)*('射擊表'!$B$2:$B$500=D31),0)),NA())} | G31: {=IFERROR(SMALL(IF('射擊表'!$A$2:$A$500=6,'射擊表'!$B$2:$B$500),30),NA())} | H31: {=IFERROR(INDEX('射擊表'!$C$2:$C$500,MATCH(1,('射擊表'!$A$2:$A$500=6)*('射擊表'!$B$2:$B$500=G31),0)),NA())} | I31: {=IFERROR(INDEX(IF('射擊表'!$E$2:$E$500="us",ABS('射擊表'!$D$2:$D$500-1500)/5,'射擊表'!$D$2:$D$500),MATCH(1,('射擊表'!$A$2:$A$500=6)*('射擊表'!$B$2:$B$500=G31),0)),NA())}
A32: {=IFERROR(SMALL(IF('射擊表'!$A$2:$A$500=4,'射擊表'!$B$2:$B$500),31),NA())} | B32: {=IFERROR(INDEX('射擊表'!$C$2:$C$500,MATCH(1,('射擊表'!$A$2:$A$500=4)*('射擊表'!$B$2:$B$500=A32),0)),NA())} | C32: {=IFERROR(INDEX(IF('射擊表'!$E$2:$E$500="us",ABS('射擊表'!$D$2:$D$500-1500)/5,'射擊表'!$D$2:$D$500),MATCH(1,('射擊表'!$A$2:$A$500=4)*('射擊表'!$B$2:$B$500=A32),0)),NA())} | D32: {=IFERROR(SMALL(IF('射擊表'!$A$2:$A$500=5,'射擊表'!$B$2:$B$500),31),NA())} | E32: {=IFERROR(INDEX('射擊表'!$C$2:$C$500,MATCH(1,('射擊表'!$A$2:$A$500=5)*('射擊表'!$B$2:$B$500=D32),0)),NA())} | F32: {=IFERROR(INDEX(IF('射擊表'!$E$2:$E$500="us",ABS('射擊表'!$D$2:$D$500-1500)/5,'射擊表'!$D$2:$D$500),MATCH(1,('射擊表'!$A$2:$A$500=5)*('射擊表'!$B$2:$B$500=D32),0)),NA())} | G32: {=IFERROR(SMALL(IF('射擊表'!$A$2:$A$500=6,'射擊表'!$B$2:$B$500),31),NA())} | H32: {=IFERROR(INDEX('射擊表'!$C$2:$C$500,MATCH(1,('射擊表'!$A$2:$A$500=6)*('射擊表'!$B$2:$B$500=G32),0)),NA())} | I32: {=IFERROR(INDEX(IF('射擊表'!$E$2:$E$500="us",ABS('射擊表'!$D$2:$D$500-1500)/5,'射擊表'!$D$2:$D$500),MATCH(1,('射擊表'!$A$2:$A$500=6)*('射擊表'!$B$2:$B$500=G32),0)),NA())}
A33: {=IFERROR(SMALL(IF('射擊表'!$A$2:$A$500=4,'射擊表'!$B$2:$B$500),32),NA())} | B33: {=IFERROR(INDEX('射擊表'!$C$2:$C$500,MATCH(1,('射擊表'!$A$2:$A$500=4)*('射擊表'!$B$2:$B$500=A33),0)),NA())} | C33: {=IFERROR(INDEX(IF('射擊表'!$E$2:$E$500="us",ABS('射擊表'!$D$2:$D$500-1500)/5,'射擊表'!$D$2:$D$500),MATCH(1,('射擊表'!$A$2:$A$500=4)*('射擊表'!$B$2:$B$500=A33),0)),NA())} | D33: {=IFERROR(SMALL(IF('射擊表'!$A$2:$A$500=5,'射擊表'!$B$2:$B$500),32),NA())} | E33: {=IFERROR(INDEX('射擊表'!$C$2:$C$500,MATCH(1,('射擊表'!$A$2:$A$500=5)*('射擊表'!$B$2:$B$500=D33),0)),NA())} | F33: {=IFERROR(INDEX(IF('射擊表'!$E$2:$E$500="us",ABS('射擊表'!$D$2:$D$500-1500)/5,'射擊表'!$D$2:$D$500),MATCH(1,('射擊表'!$A$2:$A$500=5)*('射擊表'!$B$2:$B$500=D33),0)),NA())} | G33: {=IFERROR(SMALL(IF('射擊表'!$A$2:$A$500=6,'射擊表'!$B$2:$B$500),32),NA())} | H33: {=IFERROR(INDEX('射擊表'!$C$2:$C$500,MATCH(1,('射擊表'!$A$2:$A$500=6)*('射擊表'!$B$2:$B$500=G33),0)),NA())} | I33: {=IFERROR(INDEX(IF('射擊表'!$E$2:$E$500="us",ABS('射擊表'!$D$2:$D$500-1500)/5,'射擊表'!$D$2:$D$500),MATCH(1,('射擊表'!$A$2:$A$500=6)*('射擊表'!$B$2:$B$500=G33),0)),NA())}
A34: {=IFERROR(SMALL(IF('射擊表'!$A$2:$A$500=4,'射擊表'!$B$2:$B$500),33),NA())} | B34: {=IFERROR(INDEX('射擊表'!$C$2:$C$500,MATCH(1,('射擊表'!$A$2:$A$500=4)*('射擊表'!$B$2:$B$500=A34),0)),NA())} | C34: {=IFERROR(INDEX(IF('射擊表'!$E$2:$E$500="us",ABS('射擊表'!$D$2:$D$500-1500)/5,'射擊表'!$D$2:$D$500),MATCH(1,('射擊表'!$A$2:$A$500=4)*('射擊表'!$B$2:$B$500=A34),0)),NA())} | D34: {=IFERROR(SMALL(IF('射擊表'!$A$2:$A$500=5,'射擊表'!$B$2:$B$500),33),NA())} | E34: {=IFERROR(INDEX('射擊表'!$C$2:$C$500,MATCH(1,('射擊表'!$A$2:$A$500=5)*('射擊表'!$B$2:$B$500=D34),0)),NA())} | F34: {=IFERROR(INDEX(IF('射擊表'!$E$2:$E$500="us",ABS('射擊表'!$D$2:$D$500-1500)/5,'射擊表'!$D$2:$D$500),MATCH(1,('射擊表'!$A$2:$A$500=5)*('射擊表'!$B$2:$B$500=D34),0)),NA())} | G34: {=IFERROR(SMALL(IF('射擊表'!$A$2:$A$500=6,'射擊表'!$B$2:$B$500),33),NA())} | H34: {=IFERROR(INDEX('射擊表'!$C$2:$C$500,MATCH(1,('射擊表'!$A$2:$A$500=6)*('射擊表'!$B$2:$B$500=G34),0)),NA())} | I34: {=IFERROR(INDEX(IF('射擊表'!$E$2:$E$500="us",ABS('射擊表'!$D$2:$D$500-1500)/5,'射擊表'!$D$2:$D$500),MATCH(1,('射擊表'!$A$2:$A$500=6)*('射擊表'!$B$2:$B$500=G34),0)),NA())}
A35: {=IFERROR(SMALL(IF('射擊表'!$A$2:$A$500=4,'射擊表'!$B$2:$B$500),34),NA())} | B35: {=IFERROR(INDEX('射擊表'!$C$2:$C$500,MATCH(1,('射擊表'!$A$2:$A$500=4)*('射擊表'!$B$2:$B$500=A35),0)),NA())} | C35: {=IFERROR(INDEX(IF('射擊表'!$E$2:$E$500="us",ABS('射擊表'!$D$2:$D$500-1500)/5,'射擊表'!$D$2:$D$500),MATCH(1,('射擊表'!$A$2:$A$500=4)*('射擊表'!$B$2:$B$500=A35),0)),NA())} | D35: {=IFERROR(SMALL(IF('射擊表'!$A$2:$A$500=5,'射擊表'!$B$2:$B$500),34),NA())} | E35: {=IFERROR(INDEX('射擊表'!$C$2:$C$500,MATCH(1,('射擊表'!$A$2:$A$500=5)*('射擊表'!$B$2:$B$500=D35),0)),NA())} | F35: {=IFERROR(INDEX(IF('射擊表'!$E$2:$E$500="us",ABS('射擊表'!$D$2:$D$500-1500)/5,'射擊表'!$D$2:$D$500),MATCH(1,('射擊表'!$A$2:$A$500=5)*('射擊表'!$B$2:$B$500=D35),0)),NA())} | G35: {=IFERROR(SMALL(IF('射擊表'!$A$2:$A$500=6,'射擊表'!$B$2:$B$500),34),NA())} | H35: {=IFERROR(INDEX('射擊表'!$C$2:$C$500,MATCH(1,('射擊表'!$A$2:$A$500=6)*('射擊表'!$B$2:$B$500=G35),0)),NA())} | I35: {=IFERROR(INDEX(IF('射擊表'!$E$2:$E$500="us",ABS('射擊表'!$D$2:$D$500-1500)/5,'射擊表'!$D$2:$D$500),MATCH(1,('射擊表'!$A$2:$A$500=6)*('射擊表'!$B$2:$B$500=G35),0)),NA())}
A36: {=IFERROR(SMALL(IF('射擊表'!$A$2:$A$500=4,'射擊表'!$B$2:$B$500),35),NA())} | B36: {=IFERROR(INDEX('射擊表'!$C$2:$C$500,MATCH(1,('射擊表'!$A$2:$A$500=4)*('射擊表'!$B$2:$B$500=A36),0)),NA())} | C36: {=IFERROR(INDEX(IF('射擊表'!$E$2:$E$500="us",ABS('射擊表'!$D$2:$D$500-1500)/5,'射擊表'!$D$2:$D$500),MATCH(1,('射擊表'!$A$2:$A$500=4)*('射擊表'!$B$2:$B$500=A36),0)),NA())} | D36: {=IFERROR(SMALL(IF('射擊表'!$A$2:$A$500=5,'射擊表'!$B$2:$B$500),35),NA())} | E36: {=IFERROR(INDEX('射擊表'!$C$2:$C$500,MATCH(1,('射擊表'!$A$2:$A$500=5)*('射擊表'!$B$2:$B$500=D36),0)),NA())} | F36: {=IFERROR(INDEX(IF('射擊表'!$E$2:$E$500="us",ABS('射擊表'!$D$2:$D$500-1500)/5,'射擊表'!$D$2:$D$500),MATCH(1,('射擊表'!$A$2:$A$500=5)*('射擊表'!$B$2:$B$500=D36),0)),NA())} | G36: {=IFERROR(SMALL(IF('射擊表'!$A$2:$A$500=6,'射擊表'!$B$2:$B$500),35),NA())} | H36: {=IFERROR(INDEX('射擊表'!$C$2:$C$500,MATCH(1,('射擊表'!$A$2:$A$500=6)*('射擊表'!$B$2:$B$500=G36),0)),NA())} | I36: {=IFERROR(INDEX(IF('射擊表'!$E$2:$E$500="us",ABS('射擊表'!$D$2:$D$500-1500)/5,'射擊表'!$D$2:$D$500),MATCH(1,('射擊表'!$A$2:$A$500=6)*('射擊表'!$B$2:$B$500=G36),0)),NA())}
A37: {=IFERROR(SMALL(IF('射擊表'!$A$2:$A$500=4,'射擊表'!$B$2:$B$500),36),NA())} | B37: {=IFERROR(INDEX('射擊表'!$C$2:$C$500,MATCH(1,('射擊表'!$A$2:$A$500=4)*('射擊表'!$B$2:$B$500=A37),0)),NA())} | C37: {=IFERROR(INDEX(IF('射擊表'!$E$2:$E$500="us",ABS('射擊表'!$D$2:$D$500-1500)/5,'射擊表'!$D$2:$D$500),MATCH(1,('射擊表'!$A$2:$A$500=4)*('射擊表'!$B$2:$B$500=A37),0)),NA())} | D37: {=IFERROR(SMALL(IF('射擊表'!$A$2:$A$500=5,'射擊表'!$B$2:$B$500),36),NA())} | E37: {=IFERROR(INDEX('射擊表'!$C$2:$C$500,MATCH(1,('射擊表'!$A$2:$A$500=5)*('射擊表'!$B$2:$B$500=D37),0)),NA())} | F37: {=IFERROR(INDEX(IF('射擊表'!$E$2:$E$500="us",ABS('射擊表'!$D$2:$D$500-1500)/5,'射擊表'!$D$2:$D$500),MATCH(1,('射擊表'!$A$2:$A$500=5)*('射擊表'!$B$2:$B$500=D37),0)),NA())} | G37: {=IFERROR(SMALL(IF('射擊表'!$A$2:$A$500=6,'射擊表'!$B$2:$B$500),36),NA())} | H37: {=IFERROR(INDEX('射擊表'!$C$2:$C$500,MATCH(1,('射擊表'!$A$2:$A$500=6)*('射擊表'!$B$2:$B$500=G37),0)),NA())} | I37: {=IFERROR(INDEX(IF('射擊表'!$E$2:$E$500="us",ABS('射擊表'!$D$2:$D$500-1500)/5,'射擊表'!$D$2:$D$500),MATCH(1,('射擊表'!$A$2:$A$500=6)*('射擊表'!$B$2:$B$500=G37),0)),NA())}
A38: {=IFERROR(SMALL(IF('射擊表'!$A$2:$A$500=4,'射擊表'!$B$2:$B$500),37),NA())} | B38: {=IFERROR(INDEX('射擊表'!$C$2:$C$500,MATCH(1,('射擊表'!$A$2:$A$500=4)*('射擊表'!$B$2:$B$500=A38),0)),NA())} | C38: {=IFERROR(INDEX(IF('射擊表'!$E$2:$E$500="us",ABS('射擊表'!$D$2:$D$500-1500)/5,'射擊表'!$D$2:$D$500),MATCH(1,('射擊表'!$A$2:$A$500=4)*('射擊表'!$B$2:$B$500=A38),0)),NA())} | D38: {=IFERROR(SMALL(IF('射擊表'!$A$2:$A$500=5,'射擊表'!$B$2:$B$500),37),NA())} | E38: {=IFERROR(INDEX('射擊表'!$C$2:$C$500,MATCH(1,('射擊表'!$A$2:$A$500=5)*('射擊表'!$B$2:$B$500=D38),0)),NA())} | F38: {=IFERROR(INDEX(IF('射擊表'!$E$2:$E$500="us",ABS('射擊表'!$D$2:$D$500-1500)/5,'射擊表'!$D$2:$D$500),MATCH(1,('射擊表'!$A$2:$A$500=5)*('射擊表'!$B$2:$B$500=D38),0)),NA())} | G38: {=IFERROR(SMALL(IF('射擊表'!$A$2:$A$500=6,'射擊表'!$B$2:$B$500),37),NA())} | H38: {=IFERROR(INDEX('射擊表'!$C$2:$C$500,MATCH(1,('射擊表'!$A$2:$A$500=6)*('射擊表'!$B$2:$B$500=G38),0)),NA())} | I38: {=IFERROR(INDEX(IF('射擊表'!$E$2:$E$500="us",ABS('射擊表'!$D$2:$D$500-1500)/5,'射擊表'!$D$2:$D$500),MATCH(1,('射擊表'!$A$2:$A$500=6)*('射擊表'!$B$2:$B$500=G38),0)),NA())}
A39: {=IFERROR(SMALL(IF('射擊表'!$A$2:$A$500=4,'射擊表'!$B$2:$B$500),38),NA())} | B39: {=IFERROR(INDEX('射擊表'!$C$2:$C$500,MATCH(1,('射擊表'!$A$2:$A$500=4)*('射擊表'!$B$2:$B$500=A39),0)),NA())} | C39: {=IFERROR(INDEX(IF('射擊表'!$E$2:$E$500="us",ABS('射擊表'!$D$2:$D$500-1500)/5,'射擊表'!$D$2:$D$500),MATCH(1,('射擊表'!$A$2:$A$500=4)*('射擊表'!$B$2:$B$500=A39),0)),NA())} | D39: {=IFERROR(SMALL(IF('射擊表'!$A$2:$A$500=5,'射擊表'!$B$2:$B$500),38),NA())} | E39: {=IFERROR(INDEX('射擊表'!$C$2:$C$500,MATCH(1,('射擊表'!$A$2:$A$500=5)*('射擊表'!$B$2:$B$500=D39),0)),NA())} | F39: {=IFERROR(INDEX(IF('射擊表'!$E$2:$E$500="us",ABS('射擊表'!$D$2:$D$500-1500)/5,'射擊表'!$D$2:$D$500),MATCH(1,('射擊表'!$A$2:$A$500=5)*('射擊表'!$B$2:$B$500=D39),0)),NA())} | G39: {=IFERROR(SMALL(IF('射擊表'!$A$2:$A$500=6,'射擊表'!$B$2:$B$500),38),NA())} | H39: {=IFERROR(INDEX('射擊表'!$C$2:$C$500,MATCH(1,('射擊表'!$A$2:$A$500=6)*('射擊表'!$B$2:$B$500=G39),0)),NA())} | I39: {=IFERROR(INDEX(IF('射擊表'!$E$2:$E$500="us",ABS('射擊表'!$D$2:$D$500-1500)/5,'射擊表'!$D$2:$D$500),MATCH(1,('射擊表'!$A$2:$A$500=6)*('射擊表'!$B$2:$B$500=G39),0)),NA())}
A40: {=IFERROR(SMALL(IF('射擊表'!$A$2:$A$500=4,'射擊表'!$B$2:$B$500),39),NA())} | B40: {=IFERROR(INDEX('射擊表'!$C$2:$C$500,MATCH(1,('射擊表'!$A$2:$A$500=4)*('射擊表'!$B$2:$B$500=A40),0)),NA())} | C40: {=IFERROR(INDEX(IF('射擊表'!$E$2:$E$500="us",ABS('射擊表'!$D$2:$D$500-1500)/5,'射擊表'!$D$2:$D$500),MATCH(1,('射擊表'!$A$2:$A$500=4)*('射擊表'!$B$2:$B$500=A40),0)),NA())} | D40: {=IFERROR(SMALL(IF('射擊表'!$A$2:$A$500=5,'射擊表'!$B$2:$B$500),39),NA())} | E40: {=IFERROR(INDEX('射擊表'!$C$2:$C$500,MATCH(1,('射擊表'!$A$2:$A$500=5)*('射擊表'!$B$2:$B$500=D40),0)),NA())} | F40: {=IFERROR(INDEX(IF('射擊表'!$E$2:$E$500="us",ABS('射擊表'!$D$2:$D$500-1500)/5,'射擊表'!$D$2:$D$500),MATCH(1,('射擊表'!$A$2:$A$500=5)*('射擊表'!$B$2:$B$500=D40),0)),NA())} | G40: {=IFERROR(SMALL(IF('射擊表'!$A$2:$A$500=6,'射擊表'!$B$2:$B$500),39),NA())} | H40: {=IFERROR(INDEX('射擊表'!$C$2:$C$500,MATCH(1,('射擊表'!$A$2:$A$500=6)*('射擊表'!$B$2:$B$500=G40),0)),NA())} | I40: {=IFERROR(INDEX(IF('射擊表'!$E$2:$E$500="us",ABS('射擊表'!$D$2:$D$500-1500)/5,'射擊表'!$D$2:$D$500),MATCH(1,('射擊表'!$A$2:$A$500=6)*('射擊表'!$B$2:$B$500=G40),0)),NA())}
...
